[2025-06-06 16:27:07,307] [WARNING] [real_accelerator.py:209:get_accelerator] Setting accelerator to CPU. If you have GPU or other accelerator, we were unable to detect it.
[2025-06-06 16:27:07,311] [INFO] [real_accelerator.py:254:get_accelerator] Setting ds_accelerator to cpu (auto detect)
W0606 16:27:14.774000 26203 site-packages/torch/distributed/run.py:792] 
W0606 16:27:14.774000 26203 site-packages/torch/distributed/run.py:792] *****************************************
W0606 16:27:14.774000 26203 site-packages/torch/distributed/run.py:792] Setting OMP_NUM_THREADS environment variable for each process to be 1 in default, to avoid your system being overloaded, please further tune the variable for optimal performance in your application as needed. 
W0606 16:27:14.774000 26203 site-packages/torch/distributed/run.py:792] *****************************************
/home/lengoctuong/miniconda3/envs/huatuo/bin/python3.12: can't open file '/mnt/c/Users/HOME/Downloads/HuatuoGPT-II/train_huatuo.py': [Errno 2] No such file or directory
/home/lengoctuong/miniconda3/envs/huatuo/bin/python3.12: can't open file '/mnt/c/Users/HOME/Downloads/HuatuoGPT-II/train_huatuo.py': [Errno 2] No such file or directory
/home/lengoctuong/miniconda3/envs/huatuo/bin/python3.12: can't open file '/mnt/c/Users/HOME/Downloads/HuatuoGPT-II/train_huatuo.py': [Errno 2] No such file or directory
/home/lengoctuong/miniconda3/envs/huatuo/bin/python3.12: can't open file '/mnt/c/Users/HOME/Downloads/HuatuoGPT-II/train_huatuo.py': [Errno 2] No such file or directory
/home/lengoctuong/miniconda3/envs/huatuo/bin/python3.12: can't open file '/mnt/c/Users/HOME/Downloads/HuatuoGPT-II/train_huatuo.py': [Errno 2] No such file or directory
/home/lengoctuong/miniconda3/envs/huatuo/bin/python3.12: can't open file '/mnt/c/Users/HOME/Downloads/HuatuoGPT-II/train_huatuo.py': [Errno 2] No such file or directory
/home/lengoctuong/miniconda3/envs/huatuo/bin/python3.12: can't open file '/mnt/c/Users/HOME/Downloads/HuatuoGPT-II/train_huatuo.py': [Errno 2] No such file or directory
/home/lengoctuong/miniconda3/envs/huatuo/bin/python3.12: can't open file '/mnt/c/Users/HOME/Downloads/HuatuoGPT-II/train_huatuo.py': [Errno 2] No such file or directory
E0606 16:27:14.925000 26203 site-packages/torch/distributed/elastic/multiprocessing/api.py:869] failed (exitcode: 2) local_rank: 0 (pid: 26219) of binary: /home/lengoctuong/miniconda3/envs/huatuo/bin/python3.12
Traceback (most recent call last):
  File "/home/lengoctuong/miniconda3/envs/huatuo/bin/accelerate", line 8, in <module>
    sys.exit(main())
             ^^^^^^
  File "/home/lengoctuong/miniconda3/envs/huatuo/lib/python3.12/site-packages/accelerate/commands/accelerate_cli.py", line 50, in main
    args.func(args)
  File "/home/lengoctuong/miniconda3/envs/huatuo/lib/python3.12/site-packages/accelerate/commands/launch.py", line 1183, in launch_command
    deepspeed_launcher(args)
  File "/home/lengoctuong/miniconda3/envs/huatuo/lib/python3.12/site-packages/accelerate/commands/launch.py", line 868, in deepspeed_launcher
    distrib_run.run(args)
  File "/home/lengoctuong/miniconda3/envs/huatuo/lib/python3.12/site-packages/torch/distributed/run.py", line 909, in run
    elastic_launch(
  File "/home/lengoctuong/miniconda3/envs/huatuo/lib/python3.12/site-packages/torch/distributed/launcher/api.py", line 138, in __call__
    return launch_agent(self._config, self._entrypoint, list(args))
           ^^^^^^^^^^^^^^^^^^^^^^^^^^^^^^^^^^^^^^^^^^^^^^^^^^^^^^^^
  File "/home/lengoctuong/miniconda3/envs/huatuo/lib/python3.12/site-packages/torch/distributed/launcher/api.py", line 269, in launch_agent
    raise ChildFailedError(
torch.distributed.elastic.multiprocessing.errors.ChildFailedError: 
============================================================
train_huatuo.py FAILED
------------------------------------------------------------
Failures:
[1]:
  time      : 2025-06-06_16:27:14
  host      : windows.localdomain
  rank      : 1 (local_rank: 1)
  exitcode  : 2 (pid: 26220)
  error_file: <N/A>
  traceback : To enable traceback see: https://pytorch.org/docs/stable/elastic/errors.html
[2]:
  time      : 2025-06-06_16:27:14
  host      : windows.localdomain
  rank      : 2 (local_rank: 2)
  exitcode  : 2 (pid: 26221)
  error_file: <N/A>
  traceback : To enable traceback see: https://pytorch.org/docs/stable/elastic/errors.html
[3]:
  time      : 2025-06-06_16:27:14
  host      : windows.localdomain
  rank      : 3 (local_rank: 3)
  exitcode  : 2 (pid: 26222)
  error_file: <N/A>
  traceback : To enable traceback see: https://pytorch.org/docs/stable/elastic/errors.html
[4]:
  time      : 2025-06-06_16:27:14
  host      : windows.localdomain
  rank      : 4 (local_rank: 4)
  exitcode  : 2 (pid: 26223)
  error_file: <N/A>
  traceback : To enable traceback see: https://pytorch.org/docs/stable/elastic/errors.html
[5]:
  time      : 2025-06-06_16:27:14
  host      : windows.localdomain
  rank      : 5 (local_rank: 5)
  exitcode  : 2 (pid: 26224)
  error_file: <N/A>
  traceback : To enable traceback see: https://pytorch.org/docs/stable/elastic/errors.html
[6]:
  time      : 2025-06-06_16:27:14
  host      : windows.localdomain
  rank      : 6 (local_rank: 6)
  exitcode  : 2 (pid: 26225)
  error_file: <N/A>
  traceback : To enable traceback see: https://pytorch.org/docs/stable/elastic/errors.html
[7]:
  time      : 2025-06-06_16:27:14
  host      : windows.localdomain
  rank      : 7 (local_rank: 7)
  exitcode  : 2 (pid: 26226)
  error_file: <N/A>
  traceback : To enable traceback see: https://pytorch.org/docs/stable/elastic/errors.html
------------------------------------------------------------
Root Cause (first observed failure):
[0]:
  time      : 2025-06-06_16:27:14
  host      : windows.localdomain
  rank      : 0 (local_rank: 0)
  exitcode  : 2 (pid: 26219)
  error_file: <N/A>
  traceback : To enable traceback see: https://pytorch.org/docs/stable/elastic/errors.html
============================================================
